# 返回值和错误处理

1. Result<T, E> 用于可恢复错误，panic! 宏用于不可恢复错误

## panic! 宏

### panic! 与不可恢复错误

1. panic! 宏,程序会打印出一个错误信息，展开报错点往前的函数调用堆栈，最后退出程序
2. 不可恢复的错误(梳理清楚当前场景的错误类型非常重要),一旦发生，只需让程序崩溃即可

### backtrace 栈展开

1. 缓冲区溢出

```txt
如果有过 C 语言的经验，即使你越界了，问题不大，我依然尝试去访问
至于这个值是不是你想要的（100 号内存地址也有可能有值，只不过是其它变量或者程序的！）
抱歉，不归我管，我只负责取，你要负责管理好自己的索引访问范围
```

```sh
# debug
RUST_BACKTRACE=1 cargo run | less
# release
RUST_BACKTRACE=1 cargo run --release | less
```

### panic 时的两种终止方式

1. 栈展开(默认方式)
2. 直接终止
   - 配置 Cargo.toml, 使得在 release 下 panic 时直接终止程序, 这样生成的可执行文件会更小

```toml
[profile.release]
panic = 'abort'
```

### 线程 panic

1. 如果是 main 线程 panic，则程序会终止
2. 如果是其它子线程 panic，则该线程会终止，但是不会影响 main 线程

```rust
use std::thread;

fn main() {
    // 创建一个子线程
    let handle = thread::spawn(|| {
        // 这里模拟子线程中发生了某种错误，触发 panic
        panic!("Something went wrong in the thread!");
    });

    // 等待子线程结束
    let result = handle.join();

    // 检查子线程的结果
    match result {
        Ok(_) => println!("Thread completed successfully."),
        Err(e) => println!("Thread panicked with error: {:?}", e),
    }

    // 主线程继续执行
    println!("Continuing execution in main thread.");
}
```

### 何时使用

1. 你确切的知道你的程序是正确时，可以使用 panic, 因为不太可能 panic
2. 可预期的错误则可处理，则不需要 panic
3. 后续代码的运行会受到显著影响时需要对错误 panic

```rust
#![allow(unused)]
fn main() {
    use std::net::IpAddr;
    // unwrap() 成功则返回值，失败则 panic
    // 符合第一条，panic 不太可能发生
    let home: IpAddr = "127.0.0.1".parse().unwrap();
    // expect(消息) 成功则返回值不打印消息，失败则 panic并打印消息
    let f = File::open("/dev/null").expect("Failed to open hello.txt");
    println!("{:?}", f);
}
```

### panic 原理

> 当调用 panic! 宏时，它会:

```txt
1. 格式化 panic 信息，然后使用该信息作为参数，调用 std::panic::panic_any() 函数
2. panic_any 会检查应用是否使用了 panic hook，如果使用了，该 hook 函数就会被调用（hook 是一个钩子函数，是外部代码设置的，用于在 panic 触发时，执行外部代码所需的功能）
3. 当 hook 函数返回后，当前的线程就开始进行栈展开：从 panic_any 开始，如果寄存器或者栈因为某些原因信息错乱了，那很可能该展开会发生异常，最终线程会直接停止，展开也无法继续进行
4. 展开的过程是一帧一帧的去回溯整个栈，每个帧的数据都会随之被丢弃，但是在展开过程中，你可能会遇到被用户标记为 catching 的帧（通过 std::panic::catch_unwind() 函数标记），
此时用户提供的 catch 函数会被调用，展开也随之停止：当然，如果 catch 选择在内部调用 std::panic::resume_unwind() 函数，则展开还会继续。
```

## Result<T,E>

1. 一种可处理正确值和错误的枚举

```rust
#![allow(unused)]
// 文件处理标准库
use std::fs::File;
// 错误类型标准库
use std::io::ErrorKind;

// 有一说一，这种写法嵌套太多，不够优雅
fn main() {
    let f = File::open("hello.txt");

    let f = match f {
        Ok(file) => file,
        Err(error) => match error.kind() {
            ErrorKind::NotFound => match File::create("hello.txt") {
                Ok(fc) => fc,
                Err(e) => panic!("Problem creating the file: {:?}", e),
            },
            other_error => panic!("Problem opening the file: {:?}", other_error),
        },
    };
}
```

### unwrap() 和 expect()

1. unwrap()和 expect() 是 Result<T, E> 的一个方法，如果 Result 是 Ok，则返回 Ok 中的值，如果是 Err，则调用 panic! 宏

### 将错误向上传播(?)

1. 好处：顶级处理错误 | 将错误封装发送给用户
2. 一个好的架构，往往都有一个好的错误处理系统

```rust
#![allow(unused)]
// 依旧很啰嗦
fn main() {
    use std::fs::File;
    use std::io::{self, Read};

    fn read_username_from_file() -> Result<String, io::Error> {
        // 打开文件，f是`Result<文件句柄,io::Error>`
        let f = File::open("hello.txt");

        let mut f = match f {
            // 打开文件成功，将file句柄赋值给f
            Ok(file) => file,
            // 打开文件失败，将错误返回(向上传播)
            Err(e) => return Err(e),
        };
        // 创建动态字符串s
        let mut s = String::new();
        // 从f文件句柄读取数据并写入s中
        match f.read_to_string(&mut s) {
            // 读取成功，返回Ok封装的字符串
            Ok(_) => Ok(s),
            // 将错误向上传播
            Err(e) => Err(e),
        }
    }
    let f = read_username_from_file().expect("Failed to read username");
    println!("{}", f);
}
```

```rust
#![allow(unused)]
// ? 的应用
fn main() {
    use std::error;
    use std::fs;
    use std::io;
    // 因为 read_to_string() 在 Read Trait 中实现，所以需要引入
    use std::io::Read;

    //: 简易版 60 分
    // ? 用于将错误向上传播
    // ? 的自定义使用：需要为自定义的 Error 实现 From<T> trait，并且实现 Display trait
    fn read_username_from_file() -> Result<String, io::Error> {
        // 如果结果是 Ok(T)，则把 T 赋值给 f，如果结果是 Err(E)，则 return 该错误(通用)
        let mut f = fs::File::open("hello.txt")?;
        let mut s = String::new();
        f.read_to_string(&mut s)?;
        Ok(s)
    }

    //: 简易版 80 分
    // 因为 impl error::Error for Error {}, 所以可以返回 error::Error 的 Trait 对象,这样只要实现了 error::Error 的类型都可以返回(打破局限性)
    fn read_username_from_file2() -> Result<String, Box<dyn error::Error>> {
        let mut s = String::new();
        // ? 还能实现链式调用，File::open 遇到错误就返回，没有错误就将 Ok 中的值取出来用于下一个方法调用
        fs::File::open("hello.txt")?.read_to_string(&mut s)?;
        Ok(s)
    }

    //: 简易版 100 分
    fn read_username_from_file3() -> Result<String, io::Error> {
        // 系统自带的方法，可以直接读取文件内容
        // 本质和上面一样
        fs::read_to_string("hello.txt")
    }
}
```

### ? 用于 Option<T>

```rust
#![allow(unused)]
fn main() {
    fn get(s: &[i32]) -> Option<&i32> {
        // 是这么用，但是多次一举
        let v = s.get(0)?;
        Some(v)
    }

    fn get2(s: &[i32]) -> Option<&i32> {
        // 直接返回即可
        s.get(0)
    }

    // ? 在 Option<T> 多用于链式调用
    fn last_char_of_first_line(text: &str) -> Option<char> {
        text.lines().next()?.chars().last()
    }
}
```

### 带有返回值的 main

```rust
#![allow(unused)]
use std::error::Error;
use std::fs::File;

// std::error::Error is a trait that all standard errors implement.
fn main() -> Result<(), Box<dyn Error>> {
    let f = File::open("hello.txt")?;

    Ok(())
}
```
